[2025-07-30T14:02:13.635+0000] {local_task_job_runner.py:123} INFO - ::group::Pre task execution logs
[2025-07-30T14:02:13.818+0000] {taskinstance.py:2612} INFO - Dependencies all met for dep_context=non-requeueable deps ti=<TaskInstance: dag_json_to_doris.truncate_supply_data manual__2025-07-30T14:02:07.110656+00:00 [queued]>
[2025-07-30T14:02:13.865+0000] {taskinstance.py:2612} INFO - Dependencies all met for dep_context=requeueable deps ti=<TaskInstance: dag_json_to_doris.truncate_supply_data manual__2025-07-30T14:02:07.110656+00:00 [queued]>
[2025-07-30T14:02:13.868+0000] {taskinstance.py:2865} INFO - Starting attempt 1 of 2
[2025-07-30T14:02:13.937+0000] {taskinstance.py:2888} INFO - Executing <Task(SQLExecuteQueryOperator): truncate_supply_data> on 2025-07-30 14:02:07.110656+00:00
[2025-07-30T14:02:14.050+0000] {standard_task_runner.py:104} INFO - Running: ['***', 'tasks', 'run', 'dag_json_to_doris', 'truncate_supply_data', 'manual__2025-07-30T14:02:07.110656+00:00', '--job-id', '92', '--raw', '--subdir', 'DAGS_FOLDER/dag_json_to_doris.py', '--cfg-path', '/tmp/tmpv8thcw1d']
[2025-07-30T14:02:14.028+0000] {warnings.py:112} WARNING - /home/***/.local/lib/python3.12/site-packages/***/task/task_runner/standard_task_runner.py:70: DeprecationWarning: This process (pid=534) is multi-threaded, use of fork() may lead to deadlocks in the child.
  pid = os.fork()

[2025-07-30T14:02:14.054+0000] {standard_task_runner.py:105} INFO - Job 92: Subtask truncate_supply_data
[2025-07-30T14:02:14.061+0000] {standard_task_runner.py:72} INFO - Started process 544 to run task
[2025-07-30T14:02:15.064+0000] {task_command.py:467} INFO - Running <TaskInstance: dag_json_to_doris.truncate_supply_data manual__2025-07-30T14:02:07.110656+00:00 [running]> on host 980658594ec0
[2025-07-30T14:02:21.921+0000] {taskinstance.py:3131} INFO - Exporting env vars: AIRFLOW_CTX_DAG_OWNER='reza' AIRFLOW_CTX_DAG_ID='dag_json_to_doris' AIRFLOW_CTX_TASK_ID='truncate_supply_data' AIRFLOW_CTX_EXECUTION_DATE='2025-07-30T14:02:07.110656+00:00' AIRFLOW_CTX_TRY_NUMBER='1' AIRFLOW_CTX_DAG_RUN_ID='manual__2025-07-30T14:02:07.110656+00:00'
[2025-07-30T14:02:21.971+0000] {logging_mixin.py:190} INFO - Task instance is in running state
[2025-07-30T14:02:21.976+0000] {logging_mixin.py:190} INFO -  Previous state of the Task instance: queued
[2025-07-30T14:02:21.981+0000] {logging_mixin.py:190} INFO - Current task name:truncate_supply_data state:running start_date:2025-07-30 14:02:13.830902+00:00
[2025-07-30T14:02:21.998+0000] {logging_mixin.py:190} INFO - Dag name:dag_json_to_doris and current dag run status:running
[2025-07-30T14:02:22.035+0000] {taskinstance.py:731} INFO - ::endgroup::
[2025-07-30T14:02:22.133+0000] {sql.py:266} INFO - Executing: truncate table raw.supply_data
[2025-07-30T14:02:22.380+0000] {base.py:84} INFO - Retrieving connection 'mysql_doris_conn'
[2025-07-30T14:02:22.444+0000] {base.py:84} INFO - Retrieving connection 'mysql_doris_conn'
[2025-07-30T14:02:22.576+0000] {taskinstance.py:3310} ERROR - Task failed with exception
Traceback (most recent call last):
  File "/home/airflow/.local/lib/python3.12/site-packages/airflow/models/taskinstance.py", line 767, in _execute_task
    result = _execute_callable(context=context, **execute_callable_kwargs)
             ^^^^^^^^^^^^^^^^^^^^^^^^^^^^^^^^^^^^^^^^^^^^^^^^^^^^^^^^^^^^^
  File "/home/airflow/.local/lib/python3.12/site-packages/airflow/models/taskinstance.py", line 733, in _execute_callable
    return ExecutionCallableRunner(
           ^^^^^^^^^^^^^^^^^^^^^^^^
  File "/home/airflow/.local/lib/python3.12/site-packages/airflow/utils/operator_helpers.py", line 252, in run
    return self.func(*args, **kwargs)
           ^^^^^^^^^^^^^^^^^^^^^^^^^^
  File "/home/airflow/.local/lib/python3.12/site-packages/airflow/models/baseoperator.py", line 406, in wrapper
    return func(self, *args, **kwargs)
           ^^^^^^^^^^^^^^^^^^^^^^^^^^^
  File "/home/airflow/.local/lib/python3.12/site-packages/airflow/providers/common/sql/operators/sql.py", line 272, in execute
    output = hook.run(
             ^^^^^^^^^
  File "/home/airflow/.local/lib/python3.12/site-packages/airflow/providers/common/sql/hooks/sql.py", line 452, in run
    with self._create_autocommit_connection(autocommit) as conn:
  File "/usr/local/lib/python3.12/contextlib.py", line 137, in __enter__
    return next(self.gen)
           ^^^^^^^^^^^^^^
  File "/home/airflow/.local/lib/python3.12/site-packages/airflow/providers/common/sql/hooks/sql.py", line 574, in _create_autocommit_connection
    with closing(self.get_conn()) as conn:
                 ^^^^^^^^^^^^^^^
  File "/home/airflow/.local/lib/python3.12/site-packages/airflow/providers/mysql/hooks/mysql.py", line 196, in get_conn
    return MySQLdb.connect(**conn_config)
           ^^^^^^^^^^^^^^^^^^^^^^^^^^^^^^
  File "/home/airflow/.local/lib/python3.12/site-packages/MySQLdb/__init__.py", line 121, in Connect
    return Connection(*args, **kwargs)
           ^^^^^^^^^^^^^^^^^^^^^^^^^^^
  File "/home/airflow/.local/lib/python3.12/site-packages/MySQLdb/connections.py", line 195, in __init__
    super().__init__(*args, **kwargs2)
MySQLdb.OperationalError: (2002, "Can't connect to local server through socket '/run/mysqld/mysqld.sock' (2)")
[2025-07-30T14:02:22.637+0000] {logging_mixin.py:190} INFO - Task instance in failure state
[2025-07-30T14:02:22.638+0000] {logging_mixin.py:190} INFO - Task start:2025-07-30 14:02:13.830902+00:00 end:2025-07-30 14:02:22.630854+00:00 duration:8.799952
[2025-07-30T14:02:22.639+0000] {logging_mixin.py:190} INFO - Task:<Task(SQLExecuteQueryOperator): truncate_supply_data> dag:<DAG: dag_json_to_doris> dagrun:<DagRun dag_json_to_doris @ 2025-07-30 14:02:07.110656+00:00: manual__2025-07-30T14:02:07.110656+00:00, state:running, queued_at: 2025-07-30 14:02:07.139277+00:00. externally triggered: True>
[2025-07-30T14:02:22.640+0000] {logging_mixin.py:190} INFO - Failure caused by (2002, "Can't connect to local server through socket '/run/mysqld/mysqld.sock' (2)")
[2025-07-30T14:02:22.641+0000] {taskinstance.py:1225} INFO - Marking task as UP_FOR_RETRY. dag_id=dag_json_to_doris, task_id=truncate_supply_data, run_id=manual__2025-07-30T14:02:07.110656+00:00, execution_date=20250730T140207, start_date=20250730T140213, end_date=20250730T140222
[2025-07-30T14:02:22.692+0000] {taskinstance.py:340} INFO - ::group::Post task execution logs
[2025-07-30T14:02:22.696+0000] {standard_task_runner.py:124} ERROR - Failed to execute job 92 for task truncate_supply_data ((2002, "Can't connect to local server through socket '/run/mysqld/mysqld.sock' (2)"); 544)
Traceback (most recent call last):
  File "/home/airflow/.local/lib/python3.12/site-packages/airflow/task/task_runner/standard_task_runner.py", line 117, in _start_by_fork
    ret = args.func(args, dag=self.dag)
          ^^^^^^^^^^^^^^^^^^^^^^^^^^^^^
  File "/home/airflow/.local/lib/python3.12/site-packages/airflow/cli/cli_config.py", line 49, in command
    return func(*args, **kwargs)
           ^^^^^^^^^^^^^^^^^^^^^
  File "/home/airflow/.local/lib/python3.12/site-packages/airflow/utils/cli.py", line 115, in wrapper
    return f(*args, **kwargs)
           ^^^^^^^^^^^^^^^^^^
  File "/home/airflow/.local/lib/python3.12/site-packages/airflow/cli/commands/task_command.py", line 483, in task_run
    task_return_code = _run_task_by_selected_method(args, _dag, ti)
                       ^^^^^^^^^^^^^^^^^^^^^^^^^^^^^^^^^^^^^^^^^^^^
  File "/home/airflow/.local/lib/python3.12/site-packages/airflow/cli/commands/task_command.py", line 256, in _run_task_by_selected_method
    return _run_raw_task(args, ti)
           ^^^^^^^^^^^^^^^^^^^^^^^
  File "/home/airflow/.local/lib/python3.12/site-packages/airflow/cli/commands/task_command.py", line 341, in _run_raw_task
    return ti._run_raw_task(
           ^^^^^^^^^^^^^^^^^
  File "/home/airflow/.local/lib/python3.12/site-packages/airflow/utils/session.py", line 97, in wrapper
    return func(*args, session=session, **kwargs)
           ^^^^^^^^^^^^^^^^^^^^^^^^^^^^^^^^^^^^^^
  File "/home/airflow/.local/lib/python3.12/site-packages/airflow/models/taskinstance.py", line 3004, in _run_raw_task
    return _run_raw_task(
           ^^^^^^^^^^^^^^
  File "/home/airflow/.local/lib/python3.12/site-packages/airflow/models/taskinstance.py", line 273, in _run_raw_task
    TaskInstance._execute_task_with_callbacks(
  File "/home/airflow/.local/lib/python3.12/site-packages/airflow/models/taskinstance.py", line 3158, in _execute_task_with_callbacks
    result = self._execute_task(context, task_orig)
             ^^^^^^^^^^^^^^^^^^^^^^^^^^^^^^^^^^^^^^
  File "/home/airflow/.local/lib/python3.12/site-packages/airflow/models/taskinstance.py", line 3182, in _execute_task
    return _execute_task(self, context, task_orig)
           ^^^^^^^^^^^^^^^^^^^^^^^^^^^^^^^^^^^^^^^
  File "/home/airflow/.local/lib/python3.12/site-packages/airflow/models/taskinstance.py", line 767, in _execute_task
    result = _execute_callable(context=context, **execute_callable_kwargs)
             ^^^^^^^^^^^^^^^^^^^^^^^^^^^^^^^^^^^^^^^^^^^^^^^^^^^^^^^^^^^^^
  File "/home/airflow/.local/lib/python3.12/site-packages/airflow/models/taskinstance.py", line 733, in _execute_callable
    return ExecutionCallableRunner(
           ^^^^^^^^^^^^^^^^^^^^^^^^
  File "/home/airflow/.local/lib/python3.12/site-packages/airflow/utils/operator_helpers.py", line 252, in run
    return self.func(*args, **kwargs)
           ^^^^^^^^^^^^^^^^^^^^^^^^^^
  File "/home/airflow/.local/lib/python3.12/site-packages/airflow/models/baseoperator.py", line 406, in wrapper
    return func(self, *args, **kwargs)
           ^^^^^^^^^^^^^^^^^^^^^^^^^^^
  File "/home/airflow/.local/lib/python3.12/site-packages/airflow/providers/common/sql/operators/sql.py", line 272, in execute
    output = hook.run(
             ^^^^^^^^^
  File "/home/airflow/.local/lib/python3.12/site-packages/airflow/providers/common/sql/hooks/sql.py", line 452, in run
    with self._create_autocommit_connection(autocommit) as conn:
  File "/usr/local/lib/python3.12/contextlib.py", line 137, in __enter__
    return next(self.gen)
           ^^^^^^^^^^^^^^
  File "/home/airflow/.local/lib/python3.12/site-packages/airflow/providers/common/sql/hooks/sql.py", line 574, in _create_autocommit_connection
    with closing(self.get_conn()) as conn:
                 ^^^^^^^^^^^^^^^
  File "/home/airflow/.local/lib/python3.12/site-packages/airflow/providers/mysql/hooks/mysql.py", line 196, in get_conn
    return MySQLdb.connect(**conn_config)
           ^^^^^^^^^^^^^^^^^^^^^^^^^^^^^^
  File "/home/airflow/.local/lib/python3.12/site-packages/MySQLdb/__init__.py", line 121, in Connect
    return Connection(*args, **kwargs)
           ^^^^^^^^^^^^^^^^^^^^^^^^^^^
  File "/home/airflow/.local/lib/python3.12/site-packages/MySQLdb/connections.py", line 195, in __init__
    super().__init__(*args, **kwargs2)
MySQLdb.OperationalError: (2002, "Can't connect to local server through socket '/run/mysqld/mysqld.sock' (2)")
[2025-07-30T14:02:22.756+0000] {local_task_job_runner.py:266} INFO - Task exited with return code 1
[2025-07-30T14:02:22.808+0000] {local_task_job_runner.py:245} INFO - ::endgroup::
